[2024-11-14T22:00:35.498+0000] {local_task_job_runner.py:120} INFO - ::group::Pre task execution logs
[2024-11-14T22:00:35.549+0000] {taskinstance.py:2076} INFO - Dependencies all met for dep_context=non-requeueable deps ti=<TaskInstance: build_elt_dbt.dbt_cloud manual__2024-11-14T22:00:34.744747+00:00 [queued]>
[2024-11-14T22:00:35.576+0000] {taskinstance.py:2076} INFO - Dependencies all met for dep_context=requeueable deps ti=<TaskInstance: build_elt_dbt.dbt_cloud manual__2024-11-14T22:00:34.744747+00:00 [queued]>
[2024-11-14T22:00:35.578+0000] {taskinstance.py:2306} INFO - Starting attempt 1 of 1
[2024-11-14T22:00:35.626+0000] {taskinstance.py:2330} INFO - Executing <Task(DbtCloudRunJobOperator): dbt_cloud> on 2024-11-14 22:00:34.744747+00:00
[2024-11-14T22:00:35.642+0000] {standard_task_runner.py:90} INFO - Running: ['***', 'tasks', 'run', 'build_elt_dbt', 'dbt_cloud', 'manual__2024-11-14T22:00:34.744747+00:00', '--job-id', '53', '--raw', '--subdir', 'DAGS_FOLDER/build_elt_with_dbt.py', '--cfg-path', '/tmp/tmpmmwpxd3f']
[2024-11-14T22:00:35.656+0000] {standard_task_runner.py:91} INFO - Job 53: Subtask dbt_cloud
[2024-11-14T22:00:35.667+0000] {logging_mixin.py:188} WARNING - /home/***/.local/lib/python3.12/site-packages/***/task/task_runner/standard_task_runner.py:61 DeprecationWarning: This process (pid=1991) is multi-threaded, use of fork() may lead to deadlocks in the child.
[2024-11-14T22:00:35.671+0000] {standard_task_runner.py:63} INFO - Started process 1995 to run task
[2024-11-14T22:00:35.741+0000] {task_command.py:426} INFO - Running <TaskInstance: build_elt_dbt.dbt_cloud manual__2024-11-14T22:00:34.744747+00:00 [running]> on host 88ad25095ce5
[2024-11-14T22:00:35.850+0000] {taskinstance.py:2648} INFO - Exporting env vars: AIRFLOW_CTX_DAG_OWNER='***' AIRFLOW_CTX_DAG_ID='build_elt_dbt' AIRFLOW_CTX_TASK_ID='dbt_cloud' AIRFLOW_CTX_EXECUTION_DATE='2024-11-14T22:00:34.744747+00:00' AIRFLOW_CTX_TRY_NUMBER='1' AIRFLOW_CTX_DAG_RUN_ID='manual__2024-11-14T22:00:34.744747+00:00'
[2024-11-14T22:00:35.851+0000] {taskinstance.py:430} INFO - ::endgroup::
[2024-11-14T22:00:35.881+0000] {taskinstance.py:441} INFO - ::group::Post task execution logs
[2024-11-14T22:00:35.892+0000] {taskinstance.py:2905} ERROR - Task failed with exception
Traceback (most recent call last):
  File "/home/airflow/.local/lib/python3.12/site-packages/airflow/models/taskinstance.py", line 465, in _execute_task
    result = _execute_callable(context=context, **execute_callable_kwargs)
             ^^^^^^^^^^^^^^^^^^^^^^^^^^^^^^^^^^^^^^^^^^^^^^^^^^^^^^^^^^^^^
  File "/home/airflow/.local/lib/python3.12/site-packages/airflow/models/taskinstance.py", line 432, in _execute_callable
    return execute_callable(context=context, **execute_callable_kwargs)
           ^^^^^^^^^^^^^^^^^^^^^^^^^^^^^^^^^^^^^^^^^^^^^^^^^^^^^^^^^^^^
  File "/home/airflow/.local/lib/python3.12/site-packages/airflow/models/baseoperator.py", line 400, in wrapper
    return func(self, *args, **kwargs)
           ^^^^^^^^^^^^^^^^^^^^^^^^^^^
  File "/home/airflow/.local/lib/python3.12/site-packages/airflow/providers/dbt/cloud/operators/dbt.py", line 153, in execute
    trigger_job_response = self.hook.trigger_job_run(
                           ^^^^^^^^^^^^^^^^^^^^^^^^^^
  File "/home/airflow/.local/lib/python3.12/site-packages/airflow/providers/dbt/cloud/hooks/dbt.py", line 63, in wrapper
    default_account_id = self.connection.login
                         ^^^^^^^^^^^^^^^
  File "/usr/local/lib/python3.12/functools.py", line 995, in __get__
    val = self.func(instance)
          ^^^^^^^^^^^^^^^^^^^
  File "/home/airflow/.local/lib/python3.12/site-packages/airflow/providers/dbt/cloud/hooks/dbt.py", line 279, in connection
    _connection = self.get_connection(self.dbt_cloud_conn_id)
                  ^^^^^^^^^^^^^^^^^^^^^^^^^^^^^^^^^^^^^^^^^^^
  File "/home/airflow/.local/lib/python3.12/site-packages/airflow/hooks/base.py", line 83, in get_connection
    conn = Connection.get_connection_from_secrets(conn_id)
           ^^^^^^^^^^^^^^^^^^^^^^^^^^^^^^^^^^^^^^^^^^^^^^^
  File "/home/airflow/.local/lib/python3.12/site-packages/airflow/models/connection.py", line 519, in get_connection_from_secrets
    raise AirflowNotFoundException(f"The conn_id `{conn_id}` isn't defined")
airflow.exceptions.AirflowNotFoundException: The conn_id `dbt_cloud_default` isn't defined
[2024-11-14T22:00:35.900+0000] {taskinstance.py:1206} INFO - Marking task as FAILED. dag_id=build_elt_dbt, task_id=dbt_cloud, run_id=manual__2024-11-14T22:00:34.744747+00:00, execution_date=20241114T220034, start_date=20241114T220035, end_date=20241114T220035
[2024-11-14T22:00:35.916+0000] {standard_task_runner.py:110} ERROR - Failed to execute job 53 for task dbt_cloud (The conn_id `dbt_cloud_default` isn't defined; 1995)
[2024-11-14T22:00:35.927+0000] {local_task_job_runner.py:240} INFO - Task exited with return code 1
[2024-11-14T22:00:35.949+0000] {taskinstance.py:3498} INFO - 0 downstream tasks scheduled from follow-on schedule check
[2024-11-14T22:00:35.952+0000] {local_task_job_runner.py:222} INFO - ::endgroup::
